<?xml version="1.0" ?>
<robot name="human_model" xmlns:xacro="http://www.ros.org/wiki/xacro">

 <xacro:include filename="$(find hokuyo_description)/xacro/hokuyo.gazebo.xacro" />
 <xacro:include filename="$(find hokuyo_description)/xacro/camera.gazebo.xacro" />


<xacro:property name="width" value="0.14" />
<xacro:property name="bodylen" value="0.4" />
  <link name="base_link">
    <visual>
      <origin rpy="0 0 0" xyz="0 0 0.75"/>
      <geometry>
        <cylinder length="${bodylen}" radius="${width}"/>
      </geometry>
    </visual>
  <collision>
      <geometry>
         <cylinder length="${bodylen}" radius="${width}"/>
      </geometry>
    </collision>
    <inertial>
      <mass value="24.1572"/>
      <inertia ixx="0.23674056" ixy="0.0" ixz="0.0" iyy="0.23674056" iyz="0.0" izz="0.23674056"/>
    </inertial>
  </link>


<xacro:property name="width" value="0.13" />
     <link name="human_head">
    <visual>
      <origin rpy="0 0 0" xyz="0 0 0.15"/>
      <geometry>
        <sphere radius="${width}"/>
      </geometry>
    </visual>
    <collision>
      <geometry>
         <sphere radius="${width}"/>
      </geometry>
    </collision>
     <inertial>
      <mass value="9.0344"/>
      <inertia ixx="0.23674056" ixy="0.0" ixz="0.0" iyy="0.23674056" iyz="0.0" izz="0.23674056"/>
    </inertial>
  </link>

  <joint name="base_link_to_human_head" type="revolute">
    <origin rpy="0 0 0" xyz="0 0 0.95"/>
    <axis xyz="0 0 1"/>
    <parent link="base_link"/>
    <child link="human_head"/>
  <limit effort="1" lower="-1.57079632679" upper="1.57079632679" velocity="1"/>
  </joint>


<xacro:property name="width" value="0.03" />
<xacro:property name="bodylen" value="0.21" />
 <link name="right_forearm">
    <visual>
      <origin rpy="-1.57079632679 0 0" xyz="0 0.15 0.0"/>
      <geometry>
        <cylinder length="${bodylen}" radius="${width}"/>
      </geometry>
    </visual>
   <collision>
      <geometry>
        <cylinder length="${bodylen}" radius="${width}"/>
      </geometry>
    </collision>
     <inertial>
      <mass value="0.5892"/>
      <inertia ixx="0.00026514" ixy="0.0" ixz="0.0" iyy="0.00026514" iyz="0.0" izz="0.00026514"/>
    </inertial>
  </link>

  
 <joint name="right_forearm_to_base_link" type="revolute">
    <origin rpy="0 0 0" xyz="0 0.137654678 0.935545678"/>
   <axis xyz="0 1 0"/>
    <parent link="base_link"/>
    <child link="right_forearm"/>
   <limit effort="1" lower="-1.57079632679" upper="1.57079632679" velocity="1"/>
  </joint>


<xacro:property name="width" value="0.02" />
<xacro:property name="bodylen" value="0.24" />
<link name="right_arm">
    <visual>
      <origin rpy="-1.57079632679 0 0" xyz="0 0.1 0"/>
      <geometry>
        <cylinder length="${bodylen}" radius="${width}"/>
      </geometry>
    </visual> <collision>
      <geometry>
        <cylinder length="${bodylen}" radius="${width}"/>
      </geometry>
    </collision>
    <inertial>
      <mass value="0.2946"/>
      <inertia ixx="0.00005892" ixy="0.0" ixz="0.0" iyy="0.00005892" iyz="0.0" izz="0.00005892"/>
    </inertial>
  </link>

 <joint name="right_arm_to_forearm" type="revolute">
    <origin rpy="0 0 0" xyz="0.0 0.2899 0.0"/>
   <axis xyz="1 0 0"/>
    <parent link="right_forearm"/>
    <child link="right_arm"/>
   <limit effort="1" lower="-3.14159265359" upper="0.08726646" velocity="1"/>
  </joint>


<xacro:property name="width" value="0.03" />
<xacro:property name="bodylen" value="0.21" />
<link name="left_forearm">
    <visual>
      <origin rpy="-1.57079632679 0 0" xyz="0 -0.15 0.0"/>
      <geometry>
         <cylinder length="${bodylen}" radius="${width}"/>
      </geometry>
    </visual>
    <collision>
      <geometry>
         <cylinder length="${bodylen}" radius="${width}"/>
      </geometry>
    </collision>
      <inertial>
      <mass value="0.5892"/>
      <inertia ixx="0.00026514" ixy="0.0" ixz="0.0" iyy="0.00026514" iyz="0.0" izz="0.00026514"/>
    </inertial>
  </link>

 <joint name="left_forearm_to_base_link" type="revolute">
    <origin rpy="0 0 0" xyz="0 -0.137654678 0.935545678"/>
   <axis xyz="0 1 0"/>
    <parent link="base_link"/>
    <child link="left_forearm"/>
   <limit effort="1" lower="-1.57079632679" upper="1.57079632679" velocity="1"/>
  </joint>



<xacro:property name="width" value="0.02" />
<xacro:property name="bodylen" value="0.24" />
<link name="left_arm">
    <visual>
      <origin rpy="-1.57079632679 0 0" xyz="0 -0.1 0"/>
      <geometry>
        <cylinder length="${bodylen}" radius="${width}"/>
      </geometry>
    </visual>
    <collision>
      <geometry>
        <cylinder length="${bodylen}" radius="${width}"/>
      </geometry>
    </collision>
     <inertial>
      <mass value="0.2946"/>
      <inertia ixx="0.00005892" ixy="0.0" ixz="0.0" iyy="0.00005892" iyz="0.0" izz="0.00005892"/>
    </inertial>
  </link>

 <joint name="left_arm_to_forearm" type="revolute">
    <origin rpy="0 0 0" xyz="0.0 -0.2899 0.0"/>
   <axis xyz="1 0 0"/>
    <parent link="left_forearm"/>
    <child link="left_arm"/>
   <limit effort="1" lower="-3.14159265359" upper="0.08726646" velocity="1"/>
  </joint>



<xacro:property name="width" value="0.04" />
<xacro:property name="bodylen" value="0.26" />
  <link name="right_thigh">
    <visual>
      <origin rpy="0 0 0" xyz="0 0.0 -0.14"/>
      <geometry>
        <cylinder length="${bodylen}" radius="${width}"/>
      </geometry>
    </visual>
   <collision>
      <geometry>
        <cylinder length="${bodylen}" radius="${width}"/>
      </geometry>
    </collision>
     <inertial>
      <mass value="1.2766"/>
      <inertia ixx="0.00102128" ixy="0.0" ixz="0.0" iyy="0.00102128" iyz="0.0" izz="0.00102128"/>
    </inertial>
  </link>


 <joint name="right_thigh_to_base_link" type="revolute">
    <origin rpy="0 0 0" xyz="0 -0.1 0.54"/>
   <axis xyz="0 0 1"/>
    <parent link="base_link"/>
    <child link="right_thigh"/>
   <limit effort="1" lower="0" upper="1.57079632679" velocity="1"/>
  </joint>


<xacro:property name="width" value="0.04" />
<xacro:property name="bodylen" value="0.26" />
 <link name="left_thigh">
    <visual>
      <origin rpy="0 0 0" xyz="0 0.0 -0.14"/>
      <geometry>
        <cylinder length="${bodylen}" radius="${width}"/>
      </geometry>
    </visual>
    <collision>
      <geometry>
        <cylinder length="${bodylen}" radius="${width}"/>
      </geometry>
    </collision>
      <inertial>
      <mass value="1.2766"/>
      <inertia ixx="0.00102128" ixy="0.0" ixz="0.0" iyy="0.00102128" iyz="0.0" izz="0.00102128"/>
    </inertial>
  </link>


 <joint name="left_thigh_to_base_link" type="revolute">
    <origin rpy="0 0 0" xyz="0 0.1 0.54"/>
   <axis xyz="0 0 1"/>
    <parent link="base_link"/>
    <child link="left_thigh"/>
   <limit effort="1" lower="0" upper="1.57079632679" velocity="1"/>
  </joint>


<xacro:property name="width" value="0.02" />
<xacro:property name="bodylen" value="0.2" />
 <link name="right_leg">
    <visual>
      <origin rpy="0 0 0" xyz="0 0 -0.1"/>
      <geometry>
        <cylinder length="${bodylen}" radius="${width}"/>
      </geometry>
    </visual>
     <collision>
      <geometry>
        <cylinder length="${bodylen}" radius="${width}"/>
      </geometry>
    </collision>
     <inertial>
      <mass value="0.2455"/>
      <inertia ixx="0.0000491" ixy="0.0" ixz="0.0" iyy="0.0000491" iyz="0.0" izz="0.0000491"/>
    </inertial>
  </link>


 <joint name="right_leg_to_right_thigh" type="revolute">
    <origin rpy="0 0 0" xyz="0 0 -0.27"/>
   <axis xyz="0 0 1"/>
    <parent link="right_thigh"/>
    <child link="right_leg"/>
   <limit effort="1" lower="0" upper="-1.57079632679" velocity="1"/>
  </joint>


<xacro:property name="width" value="0.02" />
<xacro:property name="bodylen" value="0.2" />
<link name="left_leg">
    <visual>
      <origin rpy="0 0 0" xyz="0 0 -0.1"/>
      <geometry>
        <cylinder length="${bodylen}" radius="${width}"/>
      </geometry>
    </visual>
    <collision>
      <geometry>
        <cylinder length="${bodylen}" radius="${width}"/>
      </geometry>
    </collision>
       <inertial>
      <mass value="0.2455"/>
      <inertia ixx="0.0000491" ixy="0.0" ixz="0.0" iyy="0.0000491" iyz="0.0" izz="0.0000491"/>
    </inertial>
  </link>


 <joint name="left_leg_to_left_thigh" type="revolute">
    <origin rpy="0 0 0" xyz="0 0 -0.27"/>
   <axis xyz="0 0 1"/>
    <parent link="left_thigh"/>
    <child link="left_leg"/>
   <limit effort="1" lower="0" upper="-1.57079632679" velocity="1"/>
  </joint>


<xacro:property name="width" value="0.02" />
<xacro:property name="bodylen" value="0.03" />
 <link name="right_ankle">
    <visual>
      <origin rpy="0 0 0" xyz="0 0 -0.025"/>
      <geometry>
        <cylinder length="${bodylen}" radius="${width}"/>
      </geometry>
    </visual>
     <collision>
      <geometry>
        <cylinder length="${bodylen}" radius="${width}"/>
      </geometry>
    </collision>
    <inertial>
      <mass value="0.036334"/>
    <inertia ixx="0.000072667" ixy="0.0" ixz="0.0" iyy="0.000072667" iyz="0.0" izz="0.000072667"/>
    </inertial>
  </link>


 <joint name="right_leg_to_right_ankle" type="revolute">
    <origin rpy="0 0 0" xyz="0 0 -0.2"/>
   <axis xyz="0 1 0"/>
    <parent link="right_leg"/>
    <child link="right_ankle"/>
   <limit effort="1" lower="-1.57079632679" upper="1.57079632679" velocity="1"/>
  </joint>


<xacro:property name="width" value="0.02" />
<xacro:property name="bodylen" value="0.03" />
 <link name="left_ankle">
    <visual>
      <origin rpy="0 0 0" xyz="0 0 -0.025"/>
      <geometry>
        <cylinder length="${bodylen}" radius="${width}"/>
      </geometry>
    </visual>
     <collision>
      <geometry>
        <cylinder length="${bodylen}" radius="${width}"/>
      </geometry>
    </collision>
      <inertial>
      <mass value="0.036334"/>
    <inertia ixx="0.000072667" ixy="0.0" ixz="0.0" iyy="0.000072667" iyz="0.0" izz="0.000072667"/>
    </inertial>
  </link>


 <joint name="left_leg_to_left_ankle" type="revolute">
    <origin rpy="0 0 0" xyz="0 0 -0.2"/>
   <axis xyz="0 1 0"/>
    <parent link="left_leg"/>
    <child link="left_ankle"/>
   <limit effort="1" lower="-1.57079632679" upper="1.57079632679" velocity="1"/>
  </joint>


<xacro:property name="width" value="0.05" />
<xacro:property name="bodylen" value="0.03" />
 <link name="right_foot">
    <visual>
      <origin rpy="0 0 0" xyz="0 0 -0.03"/>
      <geometry>
        <cylinder length="${bodylen}" radius="${width}"/>
      </geometry>
    </visual>
      <collision>
      <geometry>
        <cylinder length="${bodylen}" radius="${width}"/>
      </geometry>
    </collision>
      <inertial>
      <mass value="0.22586"/>
    <inertia ixx="0.000282325" ixy="0.0" ixz="0.0" iyy="0.000282325" iyz="0.0" izz="0.000282325"/>
    </inertial>
  </link>


 <joint name="right_foot_to_right_ankle" type="fixed">
    <origin rpy="0 0 0" xyz="0 0 0"/>
    <parent link="right_ankle"/>
    <child link="right_foot"/>
  </joint>


<xacro:property name="width" value="0.05" />
<xacro:property name="bodylen" value="0.03" />
 <link name="left_foot">
    <visual>
      <origin rpy="0 0 0" xyz="0 0 -0.03"/>
      <geometry>
        <cylinder length="${bodylen}" radius="${width}"/>
      </geometry>
    </visual>
      <collision>
      <geometry>
        <cylinder length="${bodylen}" radius="${width}"/>
      </geometry>
    </collision>
    <inertial>
      <mass value="0.22586"/>
    <inertia ixx="0.000282325" ixy="0.0" ixz="0.0" iyy="0.000282325" iyz="0.0" izz="0.000282325"/>
    </inertial>
  </link>


<joint name="left_foot_to_left_ankle" type="fixed">
    <origin rpy="0 0 0" xyz="0 0 0"/>
    <parent link="left_ankle"/>
    <child link="left_foot"/>
  </joint>

 <!-- Hokuyo -->
<xacro:property name="hokuyo_link" value="0.05" /> <!-- Size of square 'laser' box -->
 <joint name="hokuyo_joint" type="fixed">
    <axis xyz="0 1 0" />
    <origin xyz="0 0 0" rpy="0 0 0"/>
    <parent link="base_link"/>
    <child link="hokuyo_link"/>
  </joint>

   
  <link name="hokuyo_link">
    <collision>
      <origin xyz="0 0 0" rpy="0 0 0"/>
      <geometry>
    <box size="${hokuyo_link} ${hokuyo_link} ${hokuyo_link}"/>
      </geometry>
    </collision>
    
    <visual>
      <origin xyz="0 0 0" rpy="0 0 0"/>
      <geometry>
    <box size="${hokuyo_link} ${hokuyo_link} ${hokuyo_link}"/>
    <mesh filename="package://human_description/mesh//hokuyo.dae"/>
      </geometry>
      <material name="red"/>
    </visual>

    <inertial>
      <mass value="1e-5" />
      <origin xyz="0 0 0" rpy="0 0 0"/>
      <inertia ixx="1e-6" ixy="0" ixz="0" iyy="1e-6" iyz="0" izz="1e-6" />
    </inertial>
  </link>
    

 <!-- Camera -->  
 <xacro:property name="camera_link" value="0.05" /> <!-- Size of square 'camera' box -->
 <joint name="camera_joint" type="fixed">
    <axis xyz="0 1 0" />
    <origin xyz="0 0 1.26" rpy="0 0 0"/>
    <parent link="base_link"/>
    <child link="camera_link"/>
  </joint>

   
  <link name="camera_link">
    <collision>
      <origin xyz="0 0 0" rpy="0 0 0"/>
      <geometry>
    <box size="${camera_link} ${camera_link} ${camera_link}"/>
      </geometry>
    </collision>

    <visual>
      <origin xyz="0 0 0" rpy="0 0 0"/>
      <geometry>
    <box size="${camera_link} ${camera_link} ${camera_link}"/>
      </geometry>
      <material name="red"/>
    </visual>

    <inertial>
      <mass value="1e-5" />
      <origin xyz="0 0 0" rpy="0 0 0"/>
      <inertia ixx="1e-6" ixy="0" ixz="0" iyy="1e-6" iyz="0" izz="1e-6" />
    </inertial>
  </link>
     
  
</robot> 

