<?xml version="1.0" ?>
<!-- =================================================================================== -->
<!-- |    This document was autogenerated by xacro from /home/milad/ghasemi/src/human_description/urdf/human_gazebo.xacro | -->
<!-- |    EDITING THIS FILE BY HAND IS NOT RECOMMENDED                                 | -->
<!-- =================================================================================== -->
<robot name="human_model" xmlns:xacro="http://www.ros.org/wiki/xacro">
    <!-- hokuyo -->
    <gazebo reference="hokuyo_link">
        <sensor name="head_hokuyo_sensor" type="gpu_ray">
            <pose>0 0 0 0 0 0</pose>
            <visualize>true</visualize>
            <update_rate>40</update_rate>
            <ray>
                <scan>
                    <horizontal>
                        <samples>720</samples>
                        <resolution>1</resolution>
                        <min_angle>-3.14159236</min_angle>
                        <max_angle>3.14159236</max_angle>
                        <!--           <min_angle>-1.570796</min_angle>
            <max_angle>1.570796</max_angle>-->
                    </horizontal>
                </scan>
                <range>
                    <min>0.20</min>
                    <max>30.0</max>
                    <resolution>0.01</resolution>
                </range>
                <noise>
                    <type>gaussian</type>
                    <!-- Noise parameters based on published spec for Hokuyo laser
               achieving "+-30mm" accuracy at range < 10m.  A mean of 0.0m and
               stddev of 0.01m will put 99.7% of samples within 0.03m of the true
               reading. -->
                    <mean>0.0</mean>
                    <stddev>0.01</stddev>
                </noise>
            </ray>
            <plugin filename="libgazebo_ros_gpu_laser.so" name="gazebo_ros_head_hokuyo_controller">
                <topicName>/hokuyo/laser/scan</topicName>
                <frameName>hokuyo_link</frameName>
            </plugin>
        </sensor>
    </gazebo>
    <!-- camera -->
    <gazebo reference="camera_link">
        <sensor name="camera1" type="camera">
            <update_rate>30.0</update_rate>
            <camera name="head">
                <horizontal_fov>1.3962634</horizontal_fov>
                <image>
                    <width>800</width>
                    <height>800</height>
                    <format>R8G8B8</format>
                </image>
                <clip>
                    <near>0.02</near>
                    <far>300</far>
                </clip>
                <noise>
                    <type>gaussian</type>
                    <!-- Noise is sampled independently per pixel on each frame.
               That pixel's noise value is added to each of its color
               channels, which at that point lie in the range [0,1]. -->
                    <mean>0.0</mean>
                    <stddev>0.007</stddev>
                </noise>
            </camera>
            <plugin filename="libgazebo_ros_camera.so" name="camera_controller">
                <alwaysOn>true</alwaysOn>
                <updateRate>0.0</updateRate>
                <cameraName>camera/camera1</cameraName>
                <imageTopicName>image_raw</imageTopicName>
                <cameraInfoTopicName>camera_info</cameraInfoTopicName>
                <frameName>camera_link</frameName>
                <hackBaseline>0.07</hackBaseline>
                <distortionK1>0.0</distortionK1>
                <distortionK2>0.0</distortionK2>
                <distortionK3>0.0</distortionK3>
                <distortionT1>0.0</distortionT1>
                <distortionT2>0.0</distortionT2>
            </plugin>
        </sensor>
    </gazebo>
    <link name="base_link">
        <visual>
            <origin rpy="0 0 0" xyz="0 0 0.75" />
            <geometry>
                <cylinder length="0.4" radius="0.14" />
            </geometry>
        </visual>
        <collision>
            <origin rpy="0 0 0" xyz="0 0 0.75" />
            <geometry>
                <cylinder length="0.4" radius="0.14" />
            </geometry>
        </collision>

<inertial>
            <origin rpy="0 0 0" xyz="0 0 0.75" />
            <!--      <mass value="24.1572"/>
      <inertia ixx="0.23674056" ixy="0.0" ixz="0.0" iyy="0.23674056" iyz="0.0" izz="0.23674056"/>-->
            <mass value="10" />
            <inertia ixx="0.1823" ixy="0.0" ixz="0.0" iyy="0.1823" iyz="0.0" izz="0.098" />
        </inertial>

    </link>
    <link name="human_head">
        <visual>
            <origin rpy="0 0 0" xyz="0 0 0.15" />
            <geometry>
                <sphere radius="0.13" />
            </geometry>
        </visual>
        <collision>
            <origin rpy="0 0 0" xyz="0 0 0.15" />
            <geometry>
                <sphere radius="0.13" />
            </geometry>
        </collision>

<inertial>
            <origin rpy="0 0 0" xyz="0 0 0.15" />
            <!--    <mass value="9.0344"/>
      <inertia ixx="0.23674056" ixy="0.0" ixz="0.0" iyy="0.23674056" iyz="0.0" izz="0.23674056"/>-->
            <mass value="2" />
            <inertia ixx="0.01352" ixy="0.0" ixz="0.0" iyy="0.01352" iyz="0.0" izz="0.01352" />
        </inertial>

    </link>
    <joint name="base_link_to_human_head" type="revolute">
        <origin rpy="0 0 0" xyz="0 0 0.95" />
        <axis xyz="0 0 1" />
        <parent link="base_link" />
        <child link="human_head" />
        <limit effort="100.0" lower="-1.57079632679" upper="1.57079632679" velocity="0.5" />
        <dynamics damping="0.05" />
    </joint>

    <!--right_armRoll-->
    <link name="right_forearmRoll">

<inertial>
            <origin rpy="0 0 0" xyz="0.0 0.0 0.0" />
            <mass value="0.01" />
            <inertia ixx="0.0" ixy="0.0" ixz="0.0" iyy="0.0" iyz="0.0" izz="0.0" />
        </inertial>

    </link>
    <joint name="right_forearm_to_base_linkRoll" type="revolute">
        <origin rpy="0 0 0" xyz="0 -0.18 0.935545678" />
        <axis xyz="1 0 0" />
        <parent link="base_link" />
        <child link="right_forearmRoll" />
        <limit effort="100.0" lower="-1.57079632679" upper="0" velocity="0.5" />
        <!--<limit effort="100.0" lower="0" upper="0" velocity="0.5"/>-->
        <dynamics damping="0.05" />
    </joint>
    <!--right_armPitch-->
    <link name="right_forearmPitch">

<inertial>
            <origin rpy="0 0 0" xyz="0.0 0.0 0.0" />
            <mass value="0.01" />
            <inertia ixx="0.0" ixy="0.0" ixz="0.0" iyy="0.0" iyz="0.0" izz="0.0" />
        </inertial>

    </link>
    <joint name="right_forearm_to_base_linkPitch" type="revolute">
        <origin rpy="0 0 0" xyz="0 0 0" />
        <axis xyz="0 1 0" />
        <parent link="right_forearmRoll" />
        <child link="right_forearmPitch" />
        <limit effort="100.0" lower="-1.57079632679" upper="1.57079632679" velocity="0.5" />
        <!--<limit effort="100.0" lower="0" upper="0" velocity="0.5"/>-->
        <dynamics damping="0.05" />
    </joint>
    <link name="right_forearm">
        <visual>
            <origin rpy="0 0 0" xyz="0  0.0 -0.15" />
            <geometry>
                <cylinder length="0.21" radius="0.03" />
            </geometry>
        </visual>
        <collision>
            <origin rpy="0 0 0" xyz="0  0.0 -0.15" />
            <geometry>
                <cylinder length="0.21" radius="0.03" />
            </geometry>
        </collision>

<inertial>
            <origin rpy="0 -1.57079632679 0" xyz="0  0.0 -0.15" />
            <mass value="0.5892" />
            <inertia ixx="0.00026514" ixy="0.0" ixz="0.0" iyy="0.00026514" iyz="0.0" izz="0.00026514" />
        </inertial>

    </link>
    <joint name="right_forearm_to_base_linkYaw" type="revolute">
        <!--    <origin rpy="0 0 0" xyz="0 -0.18 0.935545678"/>-->
        <origin rpy="0 0 0" xyz="0 0 0" />
        <axis xyz="0 0 1" />
        <!--    <parent link="base_link"/>-->
        <parent link="right_forearmPitch" />
        <child link="right_forearm" />
        <limit effort="100.0" lower="-1.57079632679" upper="1.57079632679" velocity="0.5" />
        <dynamics damping="0.05" />
    </joint>
    <link name="right_arm">
        <visual>
            <origin rpy="0 0 0" xyz="0 0 -0.1" />
            <geometry>
                <cylinder length="0.24" radius="0.02" />
            </geometry>
        </visual>
        <collision>
            <origin rpy="0 0 0" xyz="0 0 -0.1" />
            <geometry>
                <cylinder length="0.24" radius="0.02" />
            </geometry>
        </collision>

<inertial>
            <origin rpy="0 0 0" xyz="0 0 -0.1" />
            <mass value="0.2946" />
            <inertia ixx="0.00005892" ixy="0.0" ixz="0.0" iyy="0.00005892" iyz="0.0" izz="0.00005892" />
        </inertial>

    </link>
    <joint name="right_arm_to_forearm" type="revolute">
        <origin rpy="0 0 0" xyz="0.0 0.0 -0.2899" />
        <axis xyz="0 1 0" />
        <parent link="right_forearm" />
        <child link="right_arm" />
        <!--   <limit effort="100.0" lower="-3.14159265359" upper="0.08726646" velocity="0.5"/>-->
        <limit effort="100.0" lower="-1.57079632679" upper="0.0" velocity="0.5" />
        <dynamics damping="0.05" />
    </joint>
    <!--right_hand_yaw-->
    <link name="right_hand_yaw">
     <inertial>
        <origin rpy="0 0 0" xyz="0 0 0" />
        <mass value="0.01" />
        <inertia ixx="0.0" ixy="0.0" ixz="0.0" iyy="0.0" iyz="0.0" izz="0.0" />
    </inertial>

    </link>

<!--right_hand_pitch-->
<link name="right_hand_pitch">
<inertial>
    <origin rpy="0 0 0" xyz="0 0 0" />
    <mass value="0.01" />
    <inertia ixx="0.0" ixy="0.0" ixz="0.0" iyy="0.0" iyz="0.0" izz="0.0" />
</inertial>

</link>

<!--right_hand_roll-->
<link name="right_hand_roll">
    <visual>
        <origin rpy="0 0 0" xyz="0 0 -0.03" />
        <geometry>
            <box size="0.06 0.06 0.06" />
        </geometry>
    </visual>
    <collision>
        <origin rpy="0 0 0" xyz="0 0 -0.03" />
        <geometry>
            <box size="0.06 0.06 0.06" />
        </geometry>
    </collision>

<inertial>
        <origin rpy="0 0 0" xyz="0 0 -0.03" />
        <mass value="0.1" />
        <inertia ixx="0.000001" ixy="0.0" ixz="0.0" iyy="0.000001" iyz="0.0" izz="0.000001" />
    </inertial>

</link>

<joint name="right_hand_to_arm_yaw" type="revolute">
        <origin rpy="0 0 0" xyz="0.0 0.0 -0.2" />
        <axis xyz="0 0 1" />
        <parent link="right_arm" />
        <child link="right_hand_yaw" />
        <limit effort="100.0" lower="-1.57079632679" upper="1.57079632679" velocity="0.5" />
        <dynamics damping="0.05" />
    </joint>

<joint name="right_hand_to_arm_pitch" type="revolute">
        <origin rpy="0 0 0" xyz="0.0 0.0 0.0" />
        <axis xyz="0 1 0" />
        <parent link="right_hand_yaw" />
        <child link="right_hand_pitch" />
        <limit effort="100.0" lower="-1.57079632679" upper="1.57079632679" velocity="0.5" />
        <dynamics damping="0.05" />
    </joint>

<joint name="right_hand_to_arm_roll" type="revolute">
        <origin rpy="0 0 0" xyz="0.0 0.0 0.0" />
        <axis xyz="1 0 0" />
        <parent link="right_hand_pitch" />
        <child link="right_hand_roll" />
        <limit effort="100.0" lower="-1.57079632679" upper="1.57079632679" velocity="0.5" />
        <dynamics damping="0.05" />
    </joint>


    <!--left_armRoll-->
    <link name="left_forearmRoll">

<inertial>
            <origin rpy="0 0 0" xyz="0.0 0.0 0.0" />
            <mass value="0.01" />
            <inertia ixx="0.0" ixy="0.0" ixz="0.0" iyy="0.0" iyz="0.0" izz="0.0" />
        </inertial>

    </link>
    <joint name="left_forearm_to_base_linkRoll" type="revolute">
        <origin rpy="0 0 0" xyz="0 0.18 0.935545678" />
        <axis xyz="1 0 0" />
        <parent link="base_link" />
        <child link="left_forearmRoll" />
        <limit effort="100.0" lower="0" upper="1.57079632679" velocity="0.5" />
        <!--<limit effort="100.0" lower="0" upper="0" velocity="0.5"/>-->
        <dynamics damping="0.05" />
    </joint>
    <!--left_armPitch-->
    <link name="left_forearmPitch">

<inertial>
            <origin rpy="0 0 0" xyz="0.0 0.0 0.0" />
            <mass value="0.01" />
            <inertia ixx="0.0" ixy="0.0" ixz="0.0" iyy="0.0" iyz="0.0" izz="0.0" />
        </inertial>

    </link>
    <joint name="left_forearm_to_base_linkPitch" type="revolute">
        <origin rpy="0 0 0" xyz="0 0 0" />
        <axis xyz="0 1 0" />
        <parent link="left_forearmRoll" />
        <child link="left_forearmPitch" />
        <limit effort="100.0" lower="-1.57079632679" upper="1.57079632679" velocity="0.5" />
        <!--<limit effort="100.0" lower="0" upper="0" velocity="0.5"/>-->
        <dynamics damping="0.05" />
    </joint>
    <link name="left_forearm">
        <visual>
            <origin rpy="0 0 0" xyz="0 0.0 -0.15" />
            <geometry>
                <cylinder length="0.21" radius="0.03" />
            </geometry>
        </visual>
        <collision>
            <origin rpy="0 0 0" xyz="0 0.0 -0.15" />
            <geometry>
                <cylinder length="0.21" radius="0.03" />
            </geometry>
        </collision>

<inertial>
            <origin rpy="0 0 0" xyz="0 0.0 -0.15" />
            <mass value="0.5892" />
            <inertia ixx="0.00026514" ixy="0.0" ixz="0.0" iyy="0.00026514" iyz="0.0" izz="0.00026514" />
        </inertial>

    </link>
    <joint name="left_forearm_to_base_linkYaw" type="revolute">
        <!--    <origin rpy="0 0 0" xyz="0 0.18 0.935545678"/>-->
        .
        <origin rpy="0 0 0" xyz="0 0 0" />
        <axis xyz="0 0 1" />
        <!--    <parent link="base_link"/>-->
        <parent link="left_forearmPitch" />
        <child link="left_forearm" />
        <limit effort="100.0" lower="-1.57079632679" upper="1.57079632679" velocity="0.5" />
        <dynamics damping="0.05" />
    </joint>
    <link name="left_arm">
        <visual>
            <origin rpy="0 0 0" xyz="0  0 -0.1" />
            <geometry>
                <cylinder length="0.24" radius="0.02" />
            </geometry>
        </visual>
        <collision>
            <origin rpy="0 0 0" xyz="0 0 -0.1" />
            <geometry>
                <cylinder length="0.24" radius="0.02" />
            </geometry>
        </collision>

<inertial>
            <origin rpy="0 0 0" xyz="0 0 -0.1" />
            <mass value="0.2946" />
            <inertia ixx="0.00005892" ixy="0.0" ixz="0.0" iyy="0.00005892" iyz="0.0" izz="0.00005892" />
        </inertial>

    </link>
    <joint name="left_arm_to_forearm" type="revolute">
        <origin rpy="0 0 0" xyz="0.0  0.0 -0.2899" />
        <axis xyz="0 1 0" />
        <parent link="left_forearm" />
        <child link="left_arm" />
        <!--   <limit effort="100.0" lower="-3.14159265359" upper="0.08726646" velocity="0.5"/>-->
        <limit effort="100.0" lower="-1.57079632679" upper="0.0" velocity="0.5" />
        <dynamics damping="0.05" />
    </joint>

    <!--left_hand_yaw-->
    <link name="left_hand_yaw">
     <inertial>
        <origin rpy="0 0 0" xyz="0 0 0" />
        <mass value="0.01" />
        <inertia ixx="0.0" ixy="0.0" ixz="0.0" iyy="0.0" iyz="0.0" izz="0.0" />
    </inertial>

    </link>

<!--left_hand_pitch-->
<link name="left_hand_pitch">
<inertial>
    <origin rpy="0 0 0" xyz="0 0 0" />
    <mass value="0.01" />
    <inertia ixx="0.0" ixy="0.0" ixz="0.0" iyy="0.0" iyz="0.0" izz="0.0" />
</inertial>

</link>

<!--left_hand_roll-->
<link name="left_hand_roll">
    <visual>
        <origin rpy="0 0 0" xyz="0 0 -0.03" />
        <geometry>
            <box size="0.06 0.06 0.06" />
        </geometry>
    </visual>
    <collision>
        <origin rpy="0 0 0" xyz="0 0 -0.03" />
        <geometry>
            <box size="0.06 0.06 0.06" />
        </geometry>
    </collision>

<inertial>
        <origin rpy="0 0 0" xyz="0 0 -0.03" />
        <mass value="0.1" />
        <inertia ixx="0.000001" ixy="0.0" ixz="0.0" iyy="0.000001" iyz="0.0" izz="0.000001" />
    </inertial>

</link>

<joint name="left_hand_to_arm_yaw" type="revolute">
        <origin rpy="0 0 0" xyz="0.0 0.0 -0.2" />
        <axis xyz="0 0 1" />
        <parent link="left_arm" />
        <child link="left_hand_yaw" />
        <limit effort="100.0" lower="-1.57079632679" upper="1.57079632679" velocity="0.5" />
        <dynamics damping="0.05" />
    </joint>

<joint name="left_hand_to_arm_pitch" type="revolute">
        <origin rpy="0 0 0" xyz="0.0 0.0 0.0" />
        <axis xyz="0 1 0" />
        <parent link="left_hand_yaw" />
        <child link="left_hand_pitch" />
        <limit effort="100.0" lower="-1.57079632679" upper="1.57079632679" velocity="0.5" />
        <dynamics damping="0.05" />
    </joint>

<joint name="left_hand_to_arm_roll" type="revolute">
        <origin rpy="0 0 0" xyz="0.0 0.0 0.0" />
        <axis xyz="1 0 0" />
        <parent link="left_hand_pitch" />
        <child link="left_hand_roll" />
        <limit effort="100.0" lower="-1.57079632679" upper="1.57079632679" velocity="0.5" />
        <dynamics damping="0.05" />
    </joint>


    <!--right_thighYaw-->
    <link name="right_thighYaw">

<inertial>
            <origin rpy="0 0 0" xyz="0.0 0.0 0.0" />
            <mass value="0.01" />
            <inertia ixx="0.0" ixy="0.0" ixz="0.0" iyy="0.0" iyz="0.0" izz="0.0" />
        </inertial>

    </link>
    <joint name="right_thigh_to_base_linkYaw" type="revolute">
        <origin rpy="0 0 0" xyz="0 -0.07 0.54" />
        <axis xyz="0 0 1" />
        <parent link="base_link" />
        <child link="right_thighYaw" />
        <limit effort="100.0" lower="-1.57079632679" upper="1.57079632679" velocity="0.5" />
        <!--<limit effort="100.0" lower="0" upper="0" velocity="0.5"/>-->
        <dynamics damping="0.05" />
    </joint>
    <!--right_thighRoll-->
    <link name="right_thighRoll">

<inertial>
            <origin rpy="0 0 0" xyz="0.0 0.0 0.0" />
            <mass value="0.01" />
            <inertia ixx="0.0" ixy="0.0" ixz="0.0" iyy="0.0" iyz="0.0" izz="0.0" />
        </inertial>

    </link>
    <joint name="right_thigh_to_base_linkRoll" type="revolute">
        <origin rpy="0 0 0" xyz="0 0 0" />
        <axis xyz="1 0 0" />
        <parent link="right_thighYaw" />
        <child link="right_thighRoll" />
        <limit effort="100.0" lower="-1.57079632679" upper="1.57079632679" velocity="0.5" />
        <!--   <limit effort="100.0" lower="0" upper="0" velocity="0.5"/>-->
        <dynamics damping="0.05" />
    </joint>
    <!--right_thigh-->
    <link name="right_thigh">
        <visual>
            <origin rpy="0 0 0" xyz="0 0.0 -0.14" />
            <geometry>
                <cylinder length="0.26" radius="0.04" />
            </geometry>
        </visual>
        <collision>
   <origin rpy="0 0 0" xyz="0 0.0 -0.14"/>
      <geometry>
        <cylinder length="0.26" radius="0.04" />
      </geometry>
    </collision>

<inertial>
            <origin rpy="0 0 0" xyz="0 0.0 -0.14" />
            <mass value="1.2766" />
            <inertia ixx="0.00102128" ixy="0.0" ixz="0.0" iyy="0.00102128" iyz="0.0" izz="0.00102128" />
        </inertial>

    </link>
    <joint name="right_thigh_to_base_link" type="revolute">
        <origin rpy="0 0 0" xyz="0 0 0" />
        <axis xyz="0 1 0" />
        <parent link="right_thighRoll" />
        <child link="right_thigh" />
        <limit effort="100.0" lower="-1.57079632679" upper="1.57079632679" velocity="0.5" />
        <!--   <limit effort="100.0" lower="0" upper="0" velocity="0.5"/>-->
        <dynamics damping="0.05" />
    </joint>
    <!--left_thighYaw-->
    <link name="left_thighYaw">

<inertial>
            <origin rpy="0 0 0" xyz="0.0 0.0 0.0" />
            <mass value="0.01" />
            <inertia ixx="0.0" ixy="0.0" ixz="0.0" iyy="0.0" iyz="0.0" izz="0.0" />
        </inertial>

    </link>
    <joint name="left_thigh_to_base_linkYaw" type="revolute">
        <origin rpy="0 0 0" xyz="0 0.07 0.54" />
        <axis xyz="0 0 1" />
        <parent link="base_link" />
        <child link="left_thighYaw" />
        <limit effort="100.0" lower="-1.57079632679" upper="1.57079632679" velocity="0.5" />
        <!--   <limit effort="100.0" lower="0" upper="0" velocity="0.5"/>-->
        <dynamics damping="0.05" />
    </joint>
    <!--left_thighRoll-->
    <link name="left_thighRoll">

<inertial>
            <origin rpy="0 0 0" xyz="0.0 0.0 0.0" />
            <mass value="0.01" />
            <inertia ixx="0.0" ixy="0.0" ixz="0.0" iyy="0.0" iyz="0.0" izz="0.0" />
        </inertial>

    </link>
    <joint name="left_thigh_to_base_linkRoll" type="revolute">
        <origin rpy="0 0 0" xyz="0 0 0" />
        <axis xyz="1 0 0" />
        <parent link="left_thighYaw" />
        <child link="left_thighRoll" />
        <limit effort="100.0" lower="-1.57079632679" upper="1.57079632679" velocity="0.5" />
        <!--    <limit effort="100.0" lower="0" upper="0" velocity="0.5"/>-->
        <dynamics damping="0.05" />
    </joint>
    <link name="left_thigh">
        <visual>
            <origin rpy="0 0 0" xyz="0 0.0 -0.14" />
            <geometry>
                <cylinder length="0.26" radius="0.04" />
            </geometry>
        </visual>
         <collision>
    <origin rpy="0 0 0" xyz="0 0.0 -0.14"/>
      <geometry>
        <cylinder length="0.26" radius="0.04" />
      </geometry>
    </collision>

<inertial>
            <origin rpy="0 0 0" xyz="0 0.0 -0.14" />
            <mass value="1.2766" />
            <inertia ixx="0.00102128" ixy="0.0" ixz="0.0" iyy="0.00102128" iyz="0.0" izz="0.00102128" />
        </inertial>

    </link>
    <joint name="left_thigh_to_base_link" type="revolute">
        <origin rpy="0 0 0" xyz="0 0 0" />
        <axis xyz="0 1 0" />
        <parent link="left_thighRoll" />
        <child link="left_thigh" />
        <limit effort="100.0" lower="-1.57079632679" upper="1.57079632679" velocity="0.5" />
        <!--   <limit effort="100.0" lower="0" upper="0" velocity="0.5"/>-->
        <dynamics damping="0.05" />
    </joint>
    <link name="right_leg">
        <visual>
            <origin rpy="0 0 0" xyz="0 0 -0.1" />
            <geometry>
                <cylinder length="0.2" radius="0.02" />
            </geometry>
        </visual>
        <collision>
     <origin rpy="0 0 0" xyz="0 0 -0.1"/>
      <geometry>
        <cylinder length="0.2" radius="0.02" />
      </geometry>
    </collision>

<inertial>
            <origin rpy="0 0 0" xyz="0 0 -0.1" />
            <mass value="0.2455" />
            <inertia ixx="0.0000491" ixy="0.0" ixz="0.0" iyy="0.0000491" iyz="0.0" izz="0.0000491" />
        </inertial>

    </link>
    <joint name="right_leg_to_right_thigh" type="revolute">
        <origin rpy="0 0 0" xyz="0 0 -0.27" />
        <axis xyz="0 1 0" />
        <parent link="right_thigh" />
        <child link="right_leg" />
        <limit effort="100.0" lower="-1.57079632679" upper="1.57079632679" velocity="0.5" />
        <dynamics damping="0.05" />
    </joint>
    <link name="left_leg">
        <visual>
            <origin rpy="0 0 0" xyz="0 0 -0.1" />
            <geometry>
                <cylinder length="0.2" radius="0.02" />
            </geometry>
        </visual>
        <collision>
    <origin rpy="0 0 0" xyz="0 0 -0.1"/>
      <geometry>
        <cylinder length="0.2" radius="0.02" />
      </geometry>
    </collision>

<inertial>
            <origin rpy="0 0 0" xyz="0 0 -0.1" />
            <mass value="0.2455" />
            <inertia ixx="0.0000491" ixy="0.0" ixz="0.0" iyy="0.0000491" iyz="0.0" izz="0.0000491" />
        </inertial>

    </link>
    <joint name="left_leg_to_left_thigh" type="revolute">
        <origin rpy="0 0 0" xyz="0 0 -0.27" />
        <axis xyz="0 1 0" />
        <parent link="left_thigh" />
        <child link="left_leg" />
        <limit effort="100.0" lower="-1.57079632679" upper="1.57079632679" velocity="0.5" />
        <dynamics damping="0.05" />
    </joint>
    <link name="right_ankle">
        <visual>
            <origin rpy="0 0 0" xyz="0 0 -0.025" />
            <geometry>
                <cylinder length="0.03" radius="0.02" />
            </geometry>
        </visual>
    <!--<collision>
     <origin rpy="0 0 0" xyz="0 0 -0.025"/>
      <geometry>
        <cylinder length="${bodylen}" radius="${width}"/>
      </geometry>
    </collision>-->

<inertial>
            <origin rpy="0 0 0" xyz="0 0 0" />
            <!--      <mass value="0.036334"/>
    <inertia ixx="0.000072667" ixy="0.0" ixz="0.0" iyy="0.000072667" iyz="0.0" izz="0.000072667"/>-->
            <mass value="0.01" />
            <inertia ixx="0.0" ixy="0.0" ixz="0.0" iyy="0.0" iyz="0.0" izz="0.0" />
        </inertial>

    </link>
    <joint name="right_leg_to_right_ankle" type="revolute">
        <origin rpy="0 0 0" xyz="0 0 -0.2" />
        <axis xyz="0 1 0" />
        <parent link="right_leg" />
        <child link="right_ankle" />
        <limit effort="100.0" lower="-1.57079632679" upper="1.57079632679" velocity="0.5" />
        <dynamics damping="0.05" />
    </joint>
    <link name="left_ankle">
        <visual>
            <origin rpy="0 0 0" xyz="0 0 -0.025" />
            <geometry>
                <cylinder length="0.03" radius="0.02" />
            </geometry>
        </visual>
        <!--<collision>
      <origin rpy="0 0 0" xyz="0 0 -0.025"/>
      <geometry>
        <cylinder length="${bodylen}" radius="${width}"/>
      </geometry>
    </collision>-->

<inertial>
            <origin rpy="0 0 0" xyz="0 0 0" />
            <!--<mass value="0.036334"/>
    <inertia ixx="0.000072667" ixy="0.0" ixz="0.0" iyy="0.000072667" iyz="0.0" izz="0.000072667"/>-->
            <mass value="0.01" />
            <inertia ixx="0.0" ixy="0.0" ixz="0.0" iyy="0.0" iyz="0.0" izz="0.0" />
        </inertial>

    </link>
    <joint name="left_leg_to_left_ankle" type="revolute">
        <origin rpy="0 0 0" xyz="0 0 -0.2" />
        <axis xyz="0 1 0" />
        <parent link="left_leg" />
        <child link="left_ankle" />
        <limit effort="100.0" lower="-1.57079632679" upper="1.57079632679" velocity="0.5" />
        <dynamics damping="0.05" />
    </joint>
    <link name="right_foot">
        <visual>
            <origin rpy="0 0 0" xyz="0.05 -0.01 -0.055" />
            <geometry>
                <box size="0.2 0.12 0.03" />
                <!--<cylinder length="${bodylen}" radius="${width}"/>-->
            </geometry>
        </visual>
        <collision>
            <origin rpy="0 0 0" xyz="0.05 -0.01 -0.055" />
            <geometry>
                <box size="0.2 0.12 0.03" />
                <!--<cylinder length="${bodylen}" radius="${width}"/>-->
            </geometry>
        </collision>

<inertial>
            <origin rpy="0 0 0" xyz="0 0 -0.03" />
            <mass value="0.22586" />
            <inertia ixx="0.000282325" ixy="0.0" ixz="0.0" iyy="0.000282325" iyz="0.0" izz="0.000282325" />
        </inertial>

    </link>
    <joint name="right_foot_to_right_ankle" type="revolute">
        <origin rpy="0 0 0" xyz="0 0 0" />
        <axis xyz="1 0 0" />
        <parent link="right_ankle" />
        <child link="right_foot" />
        <limit effort="100.0" lower="-1.57079632679" upper="1.57079632679" velocity="0.5" />
        <dynamics damping="0.05" />
    </joint>
    <link name="left_foot">
        <visual>
            <!--<origin rpy="0 0 0" xyz="0 0 -0.03"/>-->
            <origin rpy="0 0 0" xyz="0.05 0.01 -0.055" />
            <geometry>
                <box size="0.2 0.12 0.03" />
                <!--<cylinder length="${bodylen}" radius="${width}"/>-->
            </geometry>
        </visual>
        <collision>
            <origin rpy="0 0 0" xyz="0.05 0.01 -0.055" />
            <!-- <origin rpy="0 0 0" xyz="0 0 -0.03"/>-->
            <geometry>
                <box size="0.2 0.12 0.03" />
                <!--<cylinder length="${bodylen}" radius="${width}"/>-->
            </geometry>
        </collision>

<inertial>
            <origin rpy="0 0 0" xyz="0 0 -0.03" />
            <mass value="0.22586" />
            <inertia ixx="0.000282325" ixy="0.0" ixz="0.0" iyy="0.000282325" iyz="0.0" izz="0.000282325" />
        </inertial>

    </link>
    <joint name="left_foot_to_left_ankle" type="revolute">
        <origin rpy="0 0 0" xyz="0 0 0" />
        <axis xyz="1 0 0" />
        <parent link="left_ankle" />
        <child link="left_foot" />
        <limit effort="100.0" lower="-1.57079632679" upper="1.57079632679" velocity="0.5" />
        <dynamics damping="0.05" />
    </joint>
    <gazebo reference="right_foot">
        <mu1>20.0</mu1>
        <mu2>20.0</mu2>
        <kp>1000000.0</kp>

    </gazebo>
    <gazebo reference="left_foot">
        <mu1>20.0</mu1>
        <mu2>20.0</mu2>
        <kp>1000000.0</kp>

    </gazebo>
    <gazebo reference="left_leg">
        <laserRetro>0</laserRetro>
    </gazebo>
    <gazebo reference="right_leg">
        <laserRetro>0</laserRetro>
    </gazebo>
    <!-- Size of square 'laser' box -->
    <joint name="hokuyo_joint" type="revolute">
        <!--    <origin xyz="0.12 0.0 0.0" rpy="0 0 0"/>
    <parent link="left_foot"/>-->
        <origin rpy="0 0 0" xyz="0.0 0.0 0.2" />
        <parent link="base_link" />
        <axis xyz="0 0 1" />
        <child link="hokuyo_link" />
        <limit effort="100.0" lower="0" upper="0" velocity="0.5" />
    </joint>
    <link name="hokuyo_link">
        <!--    <collision>
      <origin xyz="0 0 0" rpy="0 0 0"/>
      <geometry>
    <box size="${hokuyo_link} ${hokuyo_link} ${hokuyo_link}"/>
      </geometry>
    </collision>-->
        <visual>
            <origin rpy="0 0 0" xyz="0 0 0" />
            <geometry>
                <box size="0.02 0.02 0.02" />
                <!--    <mesh filename="package:/human_description/mesh/hokuyo.dae"/>-->
            </geometry>
            <material name="red" />
        </visual>

<inertial>
            <mass value="0.0001" />
            <origin rpy="0 0 0" xyz="0 0 0" />
            <inertia ixx="0" ixy="0" ixz="0" iyy="0" iyz="0" izz="0" />
        </inertial>

    </link>
    <!-- aux -->
    <link name="aux_link_r">

<inertial>
            <mass value="0.0001" />
            <origin rpy="0 0 0" xyz="0 0 0" />
            <inertia ixx="0" ixy="0" ixz="0" iyy="0" iyz="0" izz="0" />
        </inertial>

    </link>
    <joint name="aux_joint_r" type="revolute">
        <origin rpy="0 0 0" xyz="0.1 0 0" />
        <axis xyz="0 0 1" />
        <parent link="right_foot" />
        <child link="aux_link_r" />
        <limit effort="100.0" lower="0" upper="0" velocity="0.5" />
    </joint>
    <link name="aux_link_l">

<inertial>
            <mass value="0.0001" />
            <origin rpy="0 0 0" xyz="0 0 0" />
            <inertia ixx="0" ixy="0" ixz="0" iyy="0" iyz="0" izz="0" />
        </inertial>

    </link>
    <joint name="aux_joint_l" type="revolute">
        <origin rpy="0 0 0" xyz="0.1 0 0" />
        <axis xyz="0 0 1" />
        <parent link="left_foot" />
        <child link="aux_link_l" />
        <limit effort="100.0" lower="0" upper="0" velocity="0.5" />
    </joint>
    <!-- Size of square 'camera' box -->
    <joint name="camera_joint" type="revolute">
        <axis xyz="0 0 1" />
        <origin rpy="0 0 0" xyz="0 0 1.26" />
        <parent link="base_link" />
        <child link="camera_link" />
        <limit effort="100.0" lower="0" upper="0" velocity="0.5" />
    </joint>
    <link name="camera_link">
        <collision>
            <origin rpy="0 0 0" xyz="0 0 0" />
            <geometry>
                <box size="0.05 0.05 0.05" />
            </geometry>
        </collision>
        <visual>
            <origin rpy="0 0 0" xyz="0 0 0" />
            <geometry>
                <box size="0.05 0.05 0.05" />
            </geometry>
            <material name="red" />
        </visual>

<inertial>
            <mass value="0.001" />
            <origin rpy="0 0 0" xyz="0 0 0" />
            <inertia ixx="0.000001" ixy="0" ixz="0" iyy="0.000001" iyz="0" izz="0.000001" />
        </inertial>

    </link>




<!--vacuum gripper-->


<link name="right_end_effector">
     <gravity>0</gravity>
     <visual>
       <origin rpy="0 0 0" xyz="0 0 0"/>
       <geometry>
         <box size="0.01 0.01 0.01"/>
       </geometry>
       <material name="transparent">
         <color rgba="0 0 0 0"/>
       </material>
     </visual>
     <inertial>
       <origin rpy="0 0 0" xyz="0.000000 0.000000 0.000000"/>
       <mass value="0.0001"/>
       <inertia ixx="1e-08" ixy="0" ixz="0" iyy="1e-08" iyz="0" izz="1e-08"/>
     </inertial>
   </link>
   <joint name="right_end_joint" type="revolute">
     <parent link="right_hand_roll" />
     <child link="right_end_effector" />
     <origin rpy="0 0 0" xyz="0 0 -.08" />
     <limit effort="30" velocity="1.0" lower="0" upper="0" />
   </joint>
  <gazebo>
     <plugin name="gazebo_ros_vacuum_gripper" filename="libgazebo_ros_vacuum_gripper.so">
       <robotNamespace>/rightgripper</robotNamespace>
       <bodyName>right_end_effector</bodyName>
       <topicName>grasping_r</topicName>
       <maxForce>200</maxForce>
       <maxDistance>0.20</maxDistance>
       <minDistance>0.001</minDistance>
     </plugin>
   </gazebo>



<link name="left_end_effector">
     <gravity>0</gravity>
     <visual>
       <origin rpy="0 0 0" xyz="0 0 0"/>
       <geometry>
         <box size="0.01 0.01 0.01"/>
       </geometry>
       <material name="transparent">
         <color rgba="0 0 0 0"/>
       </material>
     </visual>
     <inertial>
       <origin rpy="0 0 0" xyz="0.000000 0.000000 0.000000"/>
       <mass value="0.0001"/>
       <inertia ixx="1e-08" ixy="0" ixz="0" iyy="1e-08" iyz="0" izz="1e-08"/>
     </inertial>
   </link>
   <joint name="left_end_joint" type="revolute">
     <parent link="left_hand_roll" />
     <child link="left_end_effector" />
     <origin rpy="0 0 0" xyz="0 0 -.08" />
     <limit effort="30" velocity="1.0" lower="0" upper="0" />
   </joint>
   <gazebo>
     <plugin name="gazebo_ros_vacuum_gripper" filename="libgazebo_ros_vacuum_gripper.so">
       <robotNamespace>/leftgripper</robotNamespace>
       <bodyName>left_end_effector</bodyName>
       <topicName>grasping_l</topicName>
       <maxForce>200</maxForce>
       <maxDistance>0.20</maxDistance>
       <minDistance>0.001</minDistance>
     </plugin>
   </gazebo>





    <!-- transmission -->






    <transmission name="trans_base_link_to_human_head">
        <type>transmission_interface/SimpleTransmission</type>
        <joint name="base_link_to_human_head">
            <hardwareInterface>hardware_interface/EffortJointInterface</hardwareInterface>
        </joint>
        <actuator name="base_link_to_human_head_motor">
            <mechanicalReduction>1</mechanicalReduction>
        </actuator>
    </transmission>
    <transmission name="trans_right_forearm_to_base_linkRoll">
        <type>transmission_interface/SimpleTransmission</type>
        <joint name="right_forearm_to_base_linkRoll">
            <hardwareInterface>hardware_interface/PositionJointInterface</hardwareInterface>
        </joint>
        <actuator name="right_forearm_to_base_linkRoll_motor">
            <mechanicalReduction>1</mechanicalReduction>
        </actuator>
    </transmission>
    <transmission name="trans_right_forearm_to_base_linkPitch">
        <type>transmission_interface/SimpleTransmission</type>
        <joint name="right_forearm_to_base_linkPitch">
            <hardwareInterface>hardware_interface/PositionJointInterface</hardwareInterface>
        </joint>
        <actuator name="right_forearm_to_base_linkPitch_motor">
            <mechanicalReduction>1</mechanicalReduction>
        </actuator>
    </transmission>
    <transmission name="trans_right_forearm_to_base_linkYaw">
        <type>transmission_interface/SimpleTransmission</type>
        <joint name="right_forearm_to_base_linkYaw">
            <hardwareInterface>hardware_interface/PositionJointInterface</hardwareInterface>
        </joint>
        <actuator name="right_forearm_to_base_linkYaw_motor">
            <mechanicalReduction>1</mechanicalReduction>
        </actuator>
    </transmission>
    <transmission name="trans_right_arm_to_forearm">
        <type>transmission_interface/SimpleTransmission</type>
        <joint name="right_arm_to_forearm">
            <hardwareInterface>hardware_interface/PositionJointInterface</hardwareInterface>
        </joint>
        <actuator name="right_arm_to_forearm_motor">
            <mechanicalReduction>1</mechanicalReduction>
        </actuator>
    </transmission>
    <transmission name="trans_right_hand_to_arm_yaw">
        <type>transmission_interface/SimpleTransmission</type>
        <joint name="right_hand_to_arm_yaw">
            <hardwareInterface>hardware_interface/PositionJointInterface</hardwareInterface>
        </joint>
        <actuator name="right_hand_to_arm_yaw_motor">
            <mechanicalReduction>1</mechanicalReduction>
        </actuator>
    </transmission>
    <transmission name="trans_right_hand_to_arm_pitch">
        <type>transmission_interface/SimpleTransmission</type>
        <joint name="right_hand_to_arm_pitch">
            <hardwareInterface>hardware_interface/PositionJointInterface</hardwareInterface>
        </joint>
        <actuator name="right_hand_to_arm_motor_pitch">
            <mechanicalReduction>1</mechanicalReduction>
        </actuator>
    </transmission>
    <transmission name="trans_right_hand_to_arm_roll">
        <type>transmission_interface/SimpleTransmission</type>
        <joint name="right_hand_to_arm_roll">
            <hardwareInterface>hardware_interface/PositionJointInterface</hardwareInterface>
        </joint>
        <actuator name="right_hand_to_arm_motor_roll">
            <mechanicalReduction>1</mechanicalReduction>
        </actuator>
    </transmission>
    <transmission name="trans_left_forearm_to_base_linkRoll">
        <type>transmission_interface/SimpleTransmission</type>
        <joint name="left_forearm_to_base_linkRoll">
            <hardwareInterface>hardware_interface/PositionJointInterface</hardwareInterface>
        </joint>
        <actuator name="left_forearm_to_base_linkRoll_motor">
            <mechanicalReduction>1</mechanicalReduction>
        </actuator>
    </transmission>
    <transmission name="trans_left_forearm_to_base_linkPitch">
        <type>transmission_interface/SimpleTransmission</type>
        <joint name="left_forearm_to_base_linkPitch">
            <hardwareInterface>hardware_interface/PositionJointInterface</hardwareInterface>
        </joint>
        <actuator name="left_forearm_to_base_linkPitch_motor">
            <mechanicalReduction>1</mechanicalReduction>
        </actuator>
    </transmission>
    <transmission name="trans_left_forearm_to_base_linkYaw">
        <type>transmission_interface/SimpleTransmission</type>
        <joint name="left_forearm_to_base_linkYaw">
            <hardwareInterface>hardware_interface/PositionJointInterface</hardwareInterface>
        </joint>
        <actuator name="left_forearm_to_base_linkYaw_motor">
            <mechanicalReduction>1</mechanicalReduction>
        </actuator>
    </transmission>
    <transmission name="trans_left_arm_to_forearm">
        <type>transmission_interface/SimpleTransmission</type>
        <joint name="left_arm_to_forearm">
            <hardwareInterface>hardware_interface/PositionJointInterface</hardwareInterface>
        </joint>
        <actuator name="left_arm_to_forearm_motor">
            <mechanicalReduction>1</mechanicalReduction>
        </actuator>
    </transmission>
    <transmission name="trans_left_hand_yaw_to_arm">
        <type>transmission_interface/SimpleTransmission</type>
        <joint name="left_hand_to_arm_yaw">
            <hardwareInterface>hardware_interface/PositionJointInterface</hardwareInterface>
        </joint>
        <actuator name="left_hand_to_arm_yaw_motor">
            <mechanicalReduction>1</mechanicalReduction>
        </actuator>
    </transmission>
    <transmission name="trans_left_hand_to_arm_pitch">
        <type>transmission_interface/SimpleTransmission</type>
        <joint name="left_hand_to_arm_pitch">
            <hardwareInterface>hardware_interface/PositionJointInterface</hardwareInterface>
        </joint>
        <actuator name="left_hand_to_arm_pitch_motor">
            <mechanicalReduction>1</mechanicalReduction>
        </actuator>
    </transmission>
    <transmission name="trans_left_hand_to_arm_roll">
        <type>transmission_interface/SimpleTransmission</type>
        <joint name="left_hand_to_arm_roll">
            <hardwareInterface>hardware_interface/PositionJointInterface</hardwareInterface>
        </joint>
        <actuator name="left_hand_to_arm_roll_motor">
            <mechanicalReduction>1</mechanicalReduction>
        </actuator>
    </transmission>
    <transmission name="trans_right_thigh_to_base_linkYaw">
        <type>transmission_interface/SimpleTransmission</type>
        <joint name="right_thigh_to_base_linkYaw">
            <hardwareInterface>hardware_interface/EffortJointInterface</hardwareInterface>
        </joint>
        <actuator name="right_thigh_to_base_linkYaw_motor">
            <mechanicalReduction>1</mechanicalReduction>
        </actuator>
    </transmission>
    <transmission name="trans_right_thigh_to_base_linkRoll">
        <type>transmission_interface/SimpleTransmission</type>
        <joint name="right_thigh_to_base_linkRoll">
            <hardwareInterface>hardware_interface/EffortJointInterface</hardwareInterface>
        </joint>
        <actuator name="right_thigh_to_base_linkRoll_motor">
            <mechanicalReduction>1</mechanicalReduction>
        </actuator>
    </transmission>
    <transmission name="trans_right_thigh_to_base_link">
        <type>transmission_interface/SimpleTransmission</type>
        <joint name="right_thigh_to_base_link">
            <hardwareInterface>hardware_interface/EffortJointInterface</hardwareInterface>
        </joint>
        <actuator name="right_thigh_to_base_link_motor">
            <mechanicalReduction>1</mechanicalReduction>
        </actuator>
    </transmission>
    <transmission name="trans_left_thigh_to_base_linkYaw">
        <type>transmission_interface/SimpleTransmission</type>
        <joint name="left_thigh_to_base_linkYaw">
            <hardwareInterface>hardware_interface/EffortJointInterface</hardwareInterface>
        </joint>
        <actuator name="left_thigh_to_base_linkYaw_motor">
            <mechanicalReduction>1</mechanicalReduction>
        </actuator>
    </transmission>
    <transmission name="trans_left_thigh_to_base_linkRoll">
        <type>transmission_interface/SimpleTransmission</type>
        <joint name="left_thigh_to_base_linkRoll">
        <hardwareInterface>hardware_interface/EffortJointInterface</hardwareInterface>

        </joint>
        <actuator name="left_thigh_to_base_linkRoll_motor">
            <mechanicalReduction>1</mechanicalReduction>
        </actuator>
    </transmission>
    <transmission name="trans_left_thigh_to_base_link">
        <type>transmission_interface/SimpleTransmission</type>
        <joint name="left_thigh_to_base_link">
            <hardwareInterface>hardware_interface/EffortJointInterface</hardwareInterface>
        </joint>
        <actuator name="left_thigh_to_base_link_motor">
            <mechanicalReduction>1</mechanicalReduction>
        </actuator>
    </transmission>
    <transmission name="trans_right_leg_to_right_thigh">
        <type>transmission_interface/SimpleTransmission</type>
        <joint name="right_leg_to_right_thigh">
            <hardwareInterface>hardware_interface/EffortJointInterface</hardwareInterface>
        </joint>
        <actuator name="right_leg_to_right_thigh_motor">
            <mechanicalReduction>1</mechanicalReduction>
        </actuator>
    </transmission>
    <transmission name="trans_left_leg_to_left_thigh">
        <type>transmission_interface/SimpleTransmission</type>
        <joint name="left_leg_to_left_thigh">
            <hardwareInterface>hardware_interface/EffortJointInterface</hardwareInterface>
        </joint>
        <actuator name="left_leg_to_left_thigh_motor">
            <mechanicalReduction>1</mechanicalReduction>
        </actuator>
    </transmission>
    <transmission name="trans_right_leg_to_right_ankle">
        <type>transmission_interface/SimpleTransmission</type>
        <joint name="right_leg_to_right_ankle">
            <hardwareInterface>hardware_interface/EffortJointInterface</hardwareInterface>
        </joint>
        <actuator name="right_leg_to_right_ankle_motor">
            <mechanicalReduction>1</mechanicalReduction>
        </actuator>
    </transmission>
    <transmission name="trans_left_leg_to_left_ankle">
        <type>transmission_interface/SimpleTransmission</type>
        <joint name="left_leg_to_left_ankle">
            <hardwareInterface>hardware_interface/EffortJointInterface</hardwareInterface>
        </joint>
        <actuator name="left_leg_to_left_ankle_motor">
            <mechanicalReduction>1</mechanicalReduction>
        </actuator>
    </transmission>
    <transmission name="trans_right_foot_to_right_ankle">
        <type>transmission_interface/SimpleTransmission</type>
        <joint name="right_foot_to_right_ankle">
            <hardwareInterface>hardware_interface/EffortJointInterface</hardwareInterface>
        </joint>
        <actuator name="right_foot_to_right_ankle_motor">
            <mechanicalReduction>1</mechanicalReduction>
        </actuator>
    </transmission>
    <transmission name="trans_left_foot_to_left_ankle">
        <type>transmission_interface/SimpleTransmission</type>
        <joint name="left_foot_to_left_ankle">
            <hardwareInterface>hardware_interface/EffortJointInterface</hardwareInterface>
        </joint>
        <actuator name="left_foot_to_left_ankle_motor">
            <mechanicalReduction>1</mechanicalReduction>
        </actuator>
    </transmission>
    <transmission name="trans_hokuyo_joint">
        <type>transmission_interface/SimpleTransmission</type>
        <joint name="hokuyo_joint">
            <hardwareInterface>hardware_interface/EffortJointInterface</hardwareInterface>
        </joint>
        <actuator name="hokuyo_joint_motor">
            <mechanicalReduction>1</mechanicalReduction>
        </actuator>
    </transmission>
    <transmission name="trans_aux_joint_r">
        <type>transmission_interface/SimpleTransmission</type>
        <joint name="aux_joint_r">
            <hardwareInterface>hardware_interface/EffortJointInterface</hardwareInterface>
        </joint>
        <actuator name="aux_joint_r_motor">
            <mechanicalReduction>1</mechanicalReduction>
        </actuator>
    </transmission>
    <transmission name="trans_aux_joint_l">
        <type>transmission_interface/SimpleTransmission</type>
        <joint name="aux_joint_l">
            <hardwareInterface>hardware_interface/EffortJointInterface</hardwareInterface>
        </joint>
        <actuator name="aux_joint_l_motor">
            <mechanicalReduction>1</mechanicalReduction>
        </actuator>
    </transmission>
    <transmission name="trans_camera_joint">
        <type>transmission_interface/SimpleTransmission</type>
        <joint name="camera_joint">
            <hardwareInterface>hardware_interface/EffortJointInterface</hardwareInterface>
        </joint>
        <actuator name="camera_joint_motor">
            <mechanicalReduction>1</mechanicalReduction>
        </actuator>
    </transmission>

<!--<transmission name="trans_right_end_joint">
    <type>transmission_interface/SimpleTransmission</type>
    <joint name="right_end_joint">
        <hardwareInterface>hardware_interface/EffortJointInterface</hardwareInterface>
    </joint>
    <actuator name="right_end_joint_motor">
        <mechanicalReduction>1</mechanicalReduction>
    </actuator>
</transmission>-->
<!--<transmission name="trans_left_end_joint">
    <type>transmission_interface/SimpleTransmission</type>
    <joint name="left_end_joint">
        <hardwareInterface>hardware_interface/EffortJointInterface</hardwareInterface>
    </joint>
    <actuator name="left_end_joint_motor">
        <mechanicalReduction>1</mechanicalReduction>
    </actuator>
</transmission>-->

<!-- Gazebo plugin for ROS Control -->
<gazebo>
    <plugin filename="libgazebo_ros_control.so" name="gazebo_ros_control">
        <robotSimType>gazebo_ros_control/DefaultRobotHWSim</robotSimType>
        <robotNamespace>/human_model</robotNamespace>
        <legacyModeNS>true</legacyModeNS>
    </plugin>
</gazebo>

</robot>
